Workbook

Sheet Admin_Info
A1: AstraZeneca — Initiation Visit Report
A2: Version 18.0 | Form Doc Number: TMP-0010246 | Parent Doc Number: SOP-0066820
A3: Study Code | B3: Eliminate-2 (D7261C00005) | C3: Vorab
A4: Study Site Number | C4: Vorab
A5: Principal Investigator | C5: Vorab
A6: Study Site Address | C6: Vorab
A7: Monitor Name | C7: Vorab
A8: Visit Date(s) | C8: Vorab
A9: Visit Conducted | B9: In Person | C9: Vorab
A10: Reason for remote (if applicable) | C10: Vorab
A11: Monitoring Event Reviewed? | B11: Yes | C11: Vor Ort
A12: Reviewed By | C12: Vor Ort
A13: Date Review Completed | C13: Vor Ort
A14: Report Author | C14: Vorab
A15: Report Status | B15: Draft | C15: Vor Ort
A17: Colour legend: Vorab (blau) = vor dem Besuch ausfüllbar | Vor Ort (gelb) = erst am Besuchstag zu bestätigen
A19: Personnel Present
A20: Name | B20: Role / Function | C20: Present (Y/N)
B21: Principal Investigator (PI)
B22: Sub-Investigator (Sub-I)
B23: Study Coordinator (SC)
B24: Study Nurse
B25: MSLM
B26: LSAD
B27: Lead-CRA
B28: Other
B29: Other
B30: Other

Sheet Questions_Input
A1: ==IF(SUMPRODUCT((Questions_Input!J3:J75=TRUE)*(Questions_Input!E3:E75=TRUE))>0,"⚠ SITE ON HOLD — resolve outstanding HOLD items before activation","")
A2: Section | B2: Q ID | C2: Question Text | D2: Expected | E2: Has HOLD | F2: Has ISS | G2: Has ESC | H2: TIMING | I2: YOUR ANSWER ▼ | J2: IS_DEVIATION | K2: Placeholder: Date 1 | L2: Placeholder: Date 2 | M2: Placeholder: Name | N2: Placeholder: Version/Ref | O2: Notes / Comments
A3: 1 | B3: 1.1 | C3: Study rationale and objectives? | D3: Yes | E3: FALSE | F3: FALSE | G3: FALSE | H3: Vor Ort | J3: ==IF(I3="",FALSE,IF(D3="Yes",OR(I3="No",I3="NA"),IF(D3="Yes/NA",I3="No",IF(D3="No",OR(I3="Yes",I3="NA"),FALSE)))) | O3: The objective of this "pre-approval" SIV was conducted for training purposes only.
A4: 1 | B4: 1.2 | C4: Clinical Study Protocol requirements, including adherence thereto? | D4: Yes | E4: FALSE | F4: FALSE | G4: FALSE | H4: Vor Ort | J4: ==IF(I4="",FALSE,IF(D4="Yes",OR(I4="No",I4="NA"),IF(D4="Yes/NA",I4="No",IF(D4="No",OR(I4="Yes",I4="NA"),FALSE)))) | O4: Training was provided according to SIV PPT V.x.x. dated YYYY MMM DD and CSP V.X.X.
A5: 1 | B5: 1.3 | C5: Key elements of the Investigator's Brochure? | D5: Yes | E5: FALSE | F5: FALSE | G5: FALSE | H5: Vor Ort | J5: ==IF(I5="",FALSE,IF(D5="Yes",OR(I5="No",I5="NA"),IF(D5="Yes/NA",I5="No",IF(D5="No",OR(I5="Yes",I5="NA"),FALSE)))) | O5: MSLM/CRA/LSAD discussed these with the PI/SI/SC.
A6: 1 | B6: 1.4 | C6: Study timelines? | D6: Yes | E6: FALSE | F6: FALSE | G6: FALSE | H6: Vor Ort | J6: ==IF(I6="",FALSE,IF(D6="Yes",OR(I6="No",I6="NA"),IF(D6="Yes/NA",I6="No",IF(D6="No",OR(I6="Yes",I6="NA"),FALSE)))) | O6: PI/SI confirmed enrollment of 14 patients; first screening/randomization planned YYYY MM DD.
A7: 1 | B7: 1.5 | C7: Study assessments and visit schedule? | D7: Yes | E7: FALSE | F7: FALSE | G7: FALSE | H7: Vor Ort | J7: ==IF(I7="",FALSE,IF(D7="Yes",OR(I7="No",I7="NA"),IF(D7="Yes/NA",I7="No",IF(D7="No",OR(I7="Yes",I7="NA"),FALSE)))) | O7: CRA discussed in detail according to CSP V x.x.
A8: 1 | B8: 1.6 | C8: Procedures for screening, enrolment, randomisation and premature discontinuation? | D8: Yes | E8: FALSE | F8: FALSE | G8: FALSE | H8: Vor Ort | J8: ==IF(I8="",FALSE,IF(D8="Yes",OR(I8="No",I8="NA"),IF(D8="Yes/NA",I8="No",IF(D8="No",OR(I8="Yes",I8="NA"),FALSE)))) | O8: CRA discussed in detail according to CSP V x.x.
A9: 1 | B9: 1.7 | C9: Inclusion/exclusion criteria? | D9: Yes | E9: FALSE | F9: FALSE | G9: FALSE | H9: Vor Ort | J9: ==IF(I9="",FALSE,IF(D9="Yes",OR(I9="No",I9="NA"),IF(D9="Yes/NA",I9="No",IF(D9="No",OR(I9="Yes",I9="NA"),FALSE)))) | O9: CRA discussed in detail according to CSP V x.x.
A10: 1 | B10: 1.8 | C10: Subject information and consent requirements? | D10: Yes | E10: FALSE | F10: FALSE | G10: FALSE | H10: Vor Ort | J10: ==IF(I10="",FALSE,IF(D10="Yes",OR(I10="No",I10="NA"),IF(D10="Yes/NA",I10="No",IF(D10="No",OR(I10="Yes",I10="NA"),FALSE)))) | O10: CRA discussed in detail according to CSP V x.x. See also 1.1 regarding Pre-Approval nature.
A11: 1 | B11: 1.9 | C11: Adverse Event reporting? | D11: Yes | E11: FALSE | F11: FALSE | G11: FALSE | H11: Vor Ort | J11: ==IF(I11="",FALSE,IF(D11="Yes",OR(I11="No",I11="NA"),IF(D11="Yes/NA",I11="No",IF(D11="No",OR(I11="Yes",I11="NA"),FALSE)))) | O11: CRA discussed AE reporting procedures in detail according to CSP V x.x.
A12: 1 | B12: 1.10 | C12: SAE reporting, follow up process and causality? | D12: Yes | E12: FALSE | F12: FALSE | G12: FALSE | H12: Vor Ort | J12: ==IF(I12="",FALSE,IF(D12="Yes",OR(I12="No",I12="NA"),IF(D12="Yes/NA",I12="No",IF(D12="No",OR(I12="Yes",I12="NA"),FALSE)))) | O12: CRA discussed in detail according to CSP V x.x.
A13: 1 | B13: 1.11 | C13: Pregnancy, Overdose, Medication Error, Drug Misuse & Abuse procedures? | D13: Yes | E13: FALSE | F13: FALSE | G13: FALSE | H13: Vor Ort | J13: ==IF(I13="",FALSE,IF(D13="Yes",OR(I13="No",I13="NA"),IF(D13="Yes/NA",I13="No",IF(D13="No",OR(I13="Yes",I13="NA"),FALSE)))) | O13: HIGH risk for theft discussed — site to notify Monitor immediately, no later than 24h.
A14: 1 | B14: 1.12 | C14: Doses and study drug regimens including disallowed/concomitant medication? | D14: Yes | E14: FALSE | F14: FALSE | G14: FALSE | H14: Vor Ort | J14: ==IF(I14="",FALSE,IF(D14="Yes",OR(I14="No",I14="NA"),IF(D14="Yes/NA",I14="No",IF(D14="No",OR(I14="Yes",I14="NA"),FALSE)))) | O14: MSLM, CRA, LSAD discussed in detail and site is in agreement.
... A50: 8 | B50: 8.3 | C50: Were contingency plans for ePRO system failure discussed? | D50: Yes | E50: FALSE | F50: FALSE | G50: FALSE | H50: Vor Ort | J50: ==IF(I50="",FALSE,IF(D50="Yes",OR(I50="No",I50="NA"),IF(D50="Yes/NA",I50="No",IF(D50="No",OR(I50="Yes",I50="NA"),FALSE)))) | O50: CRA discussed the details with the site.
A51: 8 | B51: 8.4 | C51: Comments regarding Electronic Patient Reported Outcome. | D51: Yes | E51: FALSE | F51: FALSE | G51: FALSE | H51: Vor Ort | J51: ==IF(I51="",FALSE,IF(D51="Yes",OR(I51="No",I51="NA"),IF(D51="Yes/NA",I51="No",IF(D51="No",OR(I51="Yes",I51="NA"),FALSE))))
A52: 9 | B52: 9.1 | C52: Is an up-to-date Investigator Study File available and appropriately stored? | D52: Yes | E52: FALSE | F52: FALSE | G52: FALSE | H52: Vor Ort | J52: ==IF(I52="",FALSE,IF(D52="Yes",OR(I52="No",I52="NA"),IF(D52="Yes/NA",I52="No",IF(D52="No",OR(I52="Yes",I52="NA"),FALSE)))) | O52: ISF reviewed; documents will be provided after IEC Approval and RtE.
A53: 9 | B53: 9.2 | C53: Is a signed Clinical Study Protocol available and appropriately stored? | D53: Yes/NA | E53: FALSE | F53: FALSE | G53: FALSE | H53: Vorab | J53: ==IF(I53="",FALSE,IF(D53="Yes",OR(I53="No",I53="NA"),IF(D53="Yes/NA",I53="No",IF(D53="No",OR(I53="Yes",I53="NA"),FALSE)))) | O53: NA — Will be provided after IEC Approval; PI Signature to be collected.
A54: 9 | B54: 9.3 | C54: Are signed CSA and Source Data Agreement available and appropriately stored? | D54: Yes | E54: FALSE | F54: FALSE | G54: FALSE | H54: Vorab | J54: ==IF(I54="",FALSE,IF(D54="Yes",OR(I54="No",I54="NA"),IF(D54="Yes/NA",I54="No",IF(D54="No",OR(I54="Yes",I54="NA"),FALSE)))) | O54: CSA fully executed. SDA collected during SIV.
A55: 9 | B55: 9.4 | C55: Is a current Investigator Brochure available and appropriately stored? | D55: Yes/NA | E55: FALSE | F55: FALSE | G55: FALSE | H55: Vorab | J55: ==IF(I55="",FALSE,IF(D55="Yes",OR(I55="No",I55="NA"),IF(D55="Yes/NA",I55="No",IF(D55="No",OR(I55="Yes",I55="NA"),FALSE)))) | O55: NA — Will be provided after IEC Approval. See 1.3.
A56: 9 | B56: 9.5 | C56: Are ePRO supplies and user instructions available and stored? | D56: Yes/NA | E56: FALSE | F56: FALSE | G56: FALSE | H56: Vorab | J56: ==IF(I56="",FALSE,IF(D56="Yes",OR(I56="No",I56="NA"),IF(D56="Yes/NA",I56="No",IF(D56="No",OR(I56="Yes",I56="NA"),FALSE)))) | O56: NA — Will be provided after IEC Approval.
A57: 9 | B57: 9.6 | C57: Are Emergency unblinding tools available (if applicable)? | D57: Yes/NA | E57: FALSE | F57: FALSE | G57: FALSE | H57: Vorab | J57: ==IF(I57="",FALSE,IF(D57="Yes",OR(I57="No",I57="NA"),IF(D57="Yes/NA",I57="No",IF(D57="No",OR(I57="Yes",I57="NA"),FALSE)))) | O57: NA — Open label study.
A58: 9 | B58: 9.7 | C58: Are paper CRFs available and appropriately stored (if applicable)? | D58: Yes/NA | E58: FALSE | F58: FALSE | G58: FALSE | H58: Vorab | J58: ==IF(I58="",FALSE,IF(D58="Yes",OR(I58="No",I58="NA"),IF(D58="Yes/NA",I58="No",IF(D58="No",OR(I58="Yes",I58="NA"),FALSE)))) | O58: NA — Electronic CRF is used.
A59: 9 | B59: 9.8 | C59: Are subject diary cards, questionnaires, participation cards available and IRB/IEC-approved? | D59: Yes | E59: FALSE | F59: FALSE | G59: FALSE | H59: Vor Ort | J59: ==IF(I59="",FALSE,IF(D59="Yes",OR(I59="No",I59="NA"),IF(D59="Yes/NA",I59="No",IF(D59="No",OR(I59="Yes",I59="NA"),FALSE)))) | O59: No — Patient material will be provided after site RtE.
A60: 9 | B60: 9.9 | C60: Are laboratory supplies available and appropriately stored? | D60: Yes/NA | E60: FALSE | F60: FALSE | G60: FALSE | H60: Vorab | J60: ==IF(I60="",FALSE,IF(D60="Yes",OR(I60="No",I60="NA"),IF(D60="Yes/NA",I60="No",IF(D60="No",OR(I60="Yes",I60="NA"),FALSE)))) | O60: NA — Will be provided after IEC Approval.
A61: 9 | B61: 9.10 | C61: Is Study Drug available and appropriately stored? | D61: Yes/NA | E61: FALSE | F61: FALSE | G61: FALSE | H61: Vorab | J61: ==IF(I61="",FALSE,IF(D61="Yes",OR(I61="No",I61="NA"),IF(D61="Yes/NA",I61="No",IF(D61="No",OR(I61="Yes",I61="NA"),FALSE)))) | O61: Study drug shipment triggered once site activated in IRT system.
A62: 9 | B62: 9.11 | C62: Comments regarding Study Materials and Supplies. | D62: Yes | E62: FALSE | F62: FALSE | G62: FALSE | H62: Vor Ort | J62: ==IF(I62="",FALSE,IF(D62="Yes",OR(I62="No",I62="NA"),IF(D62="Yes/NA",I62="No",IF(D62="No",OR(I62="Yes",I62="NA"),FALSE))))
A63: 10 | B63: 10.1 | C63: Were CSA requirements and Source Data location discussed? | D63: Yes | E63: FALSE | F63: FALSE | G63: FALSE | H63: Vorab | J63: ==IF(I63="",FALSE,IF(D63="Yes",OR(I63="No",I63="NA"),IF(D63="Yes/NA",I63="No",IF(D63="No",OR(I63="Yes",I63="NA"),FALSE)))) | O63: CSA completed. CRA will have access to all needed source data.
A64: 10 | B64: 10.2 | C64: Does PI understand responsibility to supervise delegated duties? | D64: Yes | E64: FALSE | F64: FALSE | G64: FALSE | H64: Vor Ort | J64: ==IF(I64="",FALSE,IF(D64="Yes",OR(I64="No",I64="NA"),IF(D64="Yes/NA",I64="No",IF(D64="No",OR(I64="Yes",I64="NA"),FALSE)))) | O64: PI is fully aware of responsibility.
A65: 10 | B65: 10.3 | C65: Was delegation of responsibilities within Study Site Team discussed? | D65: Yes | E65: FALSE | F65: FALSE | G65: FALSE | H65: Vor Ort | J65: ==IF(I65="",FALSE,IF(D65="Yes",OR(I65="No",I65="NA"),IF(D65="Yes/NA",I65="No",IF(D65="No",OR(I65="Yes",I65="NA"),FALSE)))) | O65: DOR completed during SIV. Scan collected and will be filed in eTMF.
A66: 10 | B66: 10.4 | C66: Were ISF requirements and responsibilities discussed? | D66: Yes | E66: FALSE | F66: FALSE | G66: FALSE | H66: Vor Ort | J66: ==IF(I66="",FALSE,IF(D66="Yes",OR(I66="No",I66="NA"),IF(D66="Yes/NA",I66="No",IF(D66="No",OR(I66="Yes",I66="NA"),FALSE))))
A67: 10 | B67: 10.5 | C67: Were archiving responsibilities discussed? | D67: Yes | E67: FALSE | F67: FALSE | G67: FALSE | H67: Vor Ort | J67: ==IF(I67="",FALSE,IF(D67="Yes",OR(I67="No",I67="NA"),IF(D67="Yes/NA",I67="No",IF(D67="No",OR(I67="Yes",I67="NA"),FALSE)))) | O67: Site archive will be X.
A68: 10 | B68: 10.6 | C68: Were Financial Disclosure requirements discussed? | D68: Yes | E68: FALSE | F68: FALSE | G68: FALSE | H68: Vorab | J68: ==IF(I68="",FALSE,IF(D68="Yes",OR(I68="No",I68="NA"),IF(D68="Yes/NA",I68="No",IF(D68="No",OR(I68="Yes",I68="NA"),FALSE)))) | O68: FDFs completed and collected from PI/SI.
A69: 10 | B69: 10.7 | C69: Were potential audit/inspection responsibilities discussed? | D69: Yes | E69: FALSE | F69: FALSE | G69: FALSE | H69: Vor Ort | J69: ==IF(I69="",FALSE,IF(D69="Yes",OR(I69="No",I69="NA"),IF(D69="Yes/NA",I69="No",IF(D69="No",OR(I69="Yes",I69="NA"),FALSE)))) | O69: Site will inform CRA/LSAD immediately upon receiving any audit/inspection notification.
A70: 10 | B70: 10.8 | C70: Was site provided with AstraZeneca contact information? | D70: Yes | E70: FALSE | F70: FALSE | G70: FALSE | H70: Vorab | J70: ==IF(I70="",FALSE,IF(D70="Yes",OR(I70="No",I70="NA"),IF(D70="Yes/NA",I70="No",IF(D70="No",OR(I70="Yes",I70="NA"),FALSE)))) | O70: ISF reviewed during SIV including AZ contact information.
A71: 10 | B71: 10.9 | C71: Was site provided with WBDC IS Service Desk contact information? | D71: Yes | E71: FALSE | F71: FALSE | G71: FALSE | H71: Vorab | J71: ==IF(I71="",FALSE,IF(D71="Yes",OR(I71="No",I71="NA"),IF(D71="Yes/NA",I71="No",IF(D71="No",OR(I71="Yes",I71="NA"),FALSE))))
A72: 10 | B72: 10.10 | C72: Was site provided with ePRO Service Provider Helpdesk contact? | D72: Yes | E72: FALSE | F72: FALSE | G72: FALSE | H72: Vorab | J72: ==IF(I72="",FALSE,IF(D72="Yes",OR(I72="No",I72="NA"),IF(D72="Yes/NA",I72="No",IF(D72="No",OR(I72="Yes",I72="NA"),FALSE))))
A73: 10 | B73: 10.11 | C73: Was Sponsor obligation to provide new Safety Information discussed? | D73: Yes | E73: FALSE | F73: FALSE | G73: FALSE | H73: Vor Ort | J73: ==IF(I73="",FALSE,IF(D73="Yes",OR(I73="No",I73="NA"),IF(D73="Yes/NA",I73="No",IF(D73="No",OR(I73="Yes",I73="NA"),FALSE)))) | O73: New safety information via Veeva Site Connect; PI and SI must acknowledge electronically.
A74: 10 | B74: 10.12 | C74: Were other digital or electronic tools used in the study discussed? | D74: Yes | E74: FALSE | F74: FALSE | G74: FALSE | H74: Vor Ort | J74: ==IF(I74="",FALSE,IF(D74="Yes",OR(I74="No",I74="NA"),IF(D74="Yes/NA",I74="No",IF(D74="No",OR(I74="Yes",I74="NA"),FALSE)))) | O74: Tools: MonTE (IMP temp tracking), Signant Health, IRT & eCOA/ePRO, iMediData Rave EDC, IOVIA Central Lab, ICON Adjudication, Teckro.
A75: 10 | B75: 10.13 | C75: Comments regarding Other Study Requirements. | D75: Yes | E75: FALSE | F75: FALSE | G75: FALSE | H75: Vor Ort | J75: ==IF(I75="",FALSE,IF(D75="Yes",OR(I75="No",I75="NA"),IF(D75="Yes/NA",I75="No",IF(D75="No",OR(I75="Yes",I75="NA"),FALSE))))

Sheet Issue_Log
A1: Issue Log
A2: Issue No. | B2: Subject ID | C2: Category | D2: Summary | E2: Created By | F2: Status | G2: Issue Description | H2: Action Description | I2: Action Due Date

Sheet Observation_Log
A1: Observation Log
A2: Obs No. | B2: Priority | C2: Date Identified | D2: Summary | E2: Description | F2: Created By | G2: Status | H2: Actions Description | I2: Actions Due Date | J2: Updates | K2: Actual Completion Date

Sheet Follow_Up_Items
A1: Follow Up Items
A2: Action Item | B2: Responsible Party | C2: Status | D2: Date Identified | E2: Date Resolved | F2: Comments

Sheet Report_Comments
A1: Report Comments — Auto-generated from Questions_Input (do not edit this sheet directly)
A2: Section | B2: Q ID | C2: Section Title | D2: Generated Comment
A3: 1 | B3: 1.1 | C3: Training of Study Personnel | D3: ==IF(Questions_Input!I3="","— not yet answered —",IF(Questions_Input!J3=FALSE,"The objective of this ""pre-approval"" SIV was conducted for training purposes only."&IF(Questions_Input!O3<>""," | Note: "&Questions_Input!O3,""),"[DEVIATION] Expected: "&Questions_Input!D3&" | Actual: "&Questions_Input!I3&" — Please clarify — deviation from expected answer. Add details in Notes column."&IF(Questions_Input!O3<>""," | Details: "&Questions_Input!O3,"")))
A4: 1 | B4: 1.2 | C4: Training of Study Personnel | D4: ==IF(Questions_Input!I4="","— not yet answered —",IF(Questions_Input!J4=FALSE,"Training was provided according to SIV PPT V.x.x. dated YYYY MMM DD and CSP V.X.X."&IF(Questions_Input!O4<>""," | Note: "&Questions_Input!O4,""),"[DEVIATION] Expected: "&Questions_Input!D4&" | Actual: "&Questions_Input!I4&" — Please clarify — deviation from expected answer. Add details in Notes column."&IF(Questions_Input!O4<>""," | Details: "&Questions_Input!O4,"")))
A5: 1 | B5: 1.3 | C5: Training of Study Personnel | D5: ==IF(Questions_Input!I5="","— not yet answered —",IF(Questions_Input!J5=FALSE,"MSLM/CRA/LSAD discussed these with the PI/SI/SC."&IF(Questions_Input!O5<>""," | Note: "&Questions_Input!O5,""),"[DEVIATION] Expected: "&Questions_Input!D5&" | Actual: "&Questions_Input!I5&" — Please clarify — deviation from expected answer. Add details in Notes column."&IF(Questions_Input!O5<>""," | Details: "&Questions_Input!O5,"")))
A6: 1 | B6: 1.4 | C6: Training of Study Personnel | D6: ==IF(Questions_Input!I6="","— not yet answered —",IF(Questions_Input!J6=FALSE,"PI/SI confirmed enrollment of 14 patients; first screening/randomization planned YYYY MM DD."&IF(Questions_Input!O6<>""," | Note: "&Questions_Input!O6,""),"[DEVIATION] Expected: "&Questions_Input!D6&" | Actual: "&Questions_Input!I6&" — Please clarify — deviation from expected answer. Add details in Notes column."&IF(Questions_Input!O6<>""," | Details: "&Questions_Input!O6,"")))
A7: 1 | B7: 1.5 | C7: Training of Study Personnel | D7: ==IF(Questions_Input!I7="","— not yet answered —",IF(Questions_Input!J7=FALSE,"CRA discussed in detail according to CSP V x.x."&IF(Questions_Input!O7<>""," | Note: "&Questions_Input!O7,""),"[DEVIATION] Expected: "&Questions_Input!D7&" | Actual: "&Questions_Input!I7&" — Please clarify — deviation from expected answer. Add details in Notes column."&IF(Questions_Input!O7<>""," | Details: "&Questions_Input!O7,"")))
A8: 1 | B8: 1.6 | C8: Training of Study Personnel | D8: ==IF(Questions_Input!I8="","— not yet answered —",IF(Questions_Input!J8=FALSE,"CRA discussed in detail according to CSP V x.x."&IF(Questions_Input!O8<>""," | Note: "&Questions_Input!O8,""),"[DEVIATION] Expected: "&Questions_Input!D8&" | Actual: "&Questions_Input!I8&" — Please clarify — deviation from expected answer. Add details in Notes column."&IF(Questions_Input!O8<>""," | Details: "&Questions_Input!O8,"")))
A9: 1 | B9: 1.7 | C9: Training of Study Personnel | D9: ==IF(Questions_Input!I9="","— not yet answered —",IF(Questions_Input!J9=FALSE,"CRA discussed in detail according to CSP V x.x."&IF(Questions_Input!O9<>""," | Note: "&Questions_Input!O9,""),"[DEVIATION] Expected: "&Questions_Input!D9&" | Actual: "&Questions_Input!I9&" — Please clarify — deviation from expected answer. Add details in Notes column."&IF(Questions_Input!O9<>""," | Details: "&Questions_Input!O9,"")))
A10: 1 | B10: 1.8 | C10: Training of Study Personnel | D10: ==IF(Questions_Input!I10="","— not yet answered —",IF(Questions_Input!J10=FALSE,"CRA discussed in detail according to CSP V x.x. See also 1.1 regarding Pre-Approval nature."&IF(Questions_Input!O10<>""," | Note: "&Questions_Input!O10,""),"[DEVIATION] Expected: "&Questions_Input!D10&" | Actual: "&Questions_Input!I10&" — Please clarify — deviation from expected answer. Add details in Notes column."&IF(Questions_Input!O10<>""," | Details: "&Questions_Input!O10,"")))
A11: 1 | B11: 1.9 | C11: Training of Study Personnel | D11: ==IF(Questions_Input!I11="","— not yet answered —",IF(Questions_Input!J11=FALSE,"CRA discussed AE reporting procedures in detail according to CSP V x.x."&IF(Questions_Input!O11<>""," | Note: "&Questions_Input!O11,""),"[DEVIATION] Expected: "&Questions_Input!D11&" | Actual: "&Questions_Input!I11&" — Please clarify — deviation from expected answer. Add details in Notes column."&IF(Questions_Input!O11<>""," | Details: "&Questions_Input!O11,"")))
A12: 1 | B12: 1.10 | C12: Training of Study Personnel | D12: ==IF(Questions_Input!I12="","— not yet answered —",IF(Questions_Input!J12=FALSE,"CRA discussed in detail according to CSP V x.x."&IF(Questions_Input!O12<>""," | Note: "&Questions_Input!O12,""),"[DEVIATION] Expected: "&Questions_Input!D12&" | Actual: "&Questions_Input!I12&" — Please clarify — deviation from expected answer. Add details in Notes column."&IF(Questions_Input!O12<>""," | Details: "&Questions_Input!O12,"")))
A13: 1 | B13: 1.11 | C13: Training of Study Personnel | D13: ==IF(Questions_Input!I13="","— not yet answered —",IF(Questions_Input!J13=FALSE,"HIGH risk for theft discussed — site to notify Monitor immediately, no later than 24h."&IF(Questions_Input!O13<>""," | Note: "&Questions_Input!O13,""),"[DEVIATION] Expected: "&Questions_Input!D13&" | Actual: "&Questions_Input!I13&" — Please clarify — deviation from expected answer. Add details in Notes column."&IF(Questions_Input!O13<>""," | Details: "&Questions_Input!O13,"")))
A14: 1 | B14: 1.12 | C14: Training of Study Personnel | D14: ==IF(Questions_Input!I14="","— not yet answered —",IF(Questions_Input!J14=FALSE,"MSLM, CRA, LSAD discussed in detail and site is in agreement."&IF(Questions_Input!O14<>""," | Note: "&Questions_Input!O14,""),"[DEVIATION] Expected: "&Questions_Input!D14&" | Actual: "&Questions_Input!I14&" — Please clarify — deviation from expected answer. Add details in Notes column."&IF(Questions_Input!O14<>""," | Details: "&Questions_Input!O14,"")))
A15: 1 | B15: 1.13 | C15: Training of Study Personnel | D15: ==IF(Questions_Input!I15="","— not yet answered —",IF(Questions_Input!J15=FALSE,"MSLM, CRA, LSAD discussed in detail. See also 1.1 Pre-Approval nature."&IF(Questions_Input!O15<>""," | Note: "&Questions_Input!O15,""),"[DEVIATION] Expected: "&Questions_Input!D15&" | Actual: "&Questions_Input!I15&" — Please clarify — deviation from expected answer. Add details in Notes column."&IF(Questions_Input!O15<>""," | Details: "&Questions_Input!O15,"")))
A16: 1 | B16: 1.14 | C16: Training of Study Personnel | D16: ==IF(Questions_Input!I16="","— not yet answered —",IF(Questions_Input!J16=FALSE,"NA — This study is open label."&IF(Questions_Input!O16<>""," | Note: "&Questions_Input!O16,""),"[DEVIATION] Expected: "&Questions_Input!D16&" | Actual: "&Questions_Input!I16&" — Please clarify — deviation from expected answer. Add details in Notes column."&IF(Questions_Input!O16<>""," | Details: "&Questions_Input!O16,"")))
A17: 1 | B17: 1.14.1 | C17: Training of Study Personnel | D17: ==IF(Questions_Input!I17="","— not yet answered —",IF(Questions_Input!J17=FALSE,"NA — This study is open label."&IF(Questions_Input!O17<>""," | Note: "&Questions_Input!O17,""),"[DEVIATION] Expected: "&Questions_Input!D17&" | Actual: "&Questions_Input!I17&" — Please clarify — deviation from expected answer. Add details in Notes column."&IF(Questions_Input!O17<>""," | Details: "&Questions_Input!O17,"")))
A18: 1 | B18: 1.15 | C18: Training of Study Personnel | D18: ==IF(Questions_Input!I18="","— not yet answered —",IF(Questions_Input!J18=FALSE,"CRA discussed in detail; site is in agreement."&IF(Questions_Input!O18<>""," | Note: "&Questions_Input!O18,""),"[DEVIATION] Expected: "&Questions_Input!D18&" | Actual: "&Questions_Input!I18&" — Please clarify — deviation from expected answer. Add details in Notes column."&IF(Questions_Input!O18<>""," | Details: "&Questions_Input!O18,"")))
A19: 1 | B19: 1.16 | C19: Training of Study Personnel | D19: ==IF(Questions_Input!I19="","— not yet answered —",IF(Questions_Input!J19=FALSE,"CRA discussed with the site in detail."&IF(Questions_Input!O19<>""," | Note: "&Questions_Input!O19,""),"[DEVIATION] Expected: "&Questions_Input!D19&" | Actual: "&Questions_Input!I19&" — Please clarify — deviation from expected answer. Add details in Notes column."&IF(Questions_Input!O19<>""," | Details: "&Questions_Input!O19,"")))
A20: 1 | B20: 1.17 | C20: Training of Study Personnel | D20: ==IF(Questions_Input!I20="","— not yet answered —",IF(Questions_Input!J20=FALSE,"NA."&IF(Questions_Input!O20<>""," | Note: "&Questions_Input!O20,""),"[DEVIATION] Expected: "&Questions_Input!D20&" | Actual: "&Questions_Input!I20&" — Please clarify — deviation from expected answer. Add details in Notes column."&IF(Questions_Input!O20<>""," | Details: "&Questions_Input!O20,"")))
A21: 1 | B21: 1.18 | C21: Training of Study Personnel | D21: ==IF(Questions_Input!I21="","— not yet answered —",IF(Questions_Input!J21=FALSE,"All certificates and calibrations are in place and were reviewed."&IF(Questions_Input!O21<>""," | Note: "&Questions_Input!O21,""),"[DEVIATION] Expected: "&Questions_Input!D21&" | Actual: "&Questions_Input!I21&" — Please clarify — deviation from expected answer. Add details in Notes column."&IF(Questions_Input!O21<>""," | Details: "&Questions_Input!O21,"")))
A22: 1 | B22: 1.19 | C22: Training of Study Personnel | D22: ==IF(Questions_Input!I22="","— not yet answered —",IF(Questions_Input!J22=FALSE,"Site is fully trained and accesses are working/were requested."&IF(Questions_Input!O22<>""," | Note: "&Questions_Input!O22,""),"[DEVIATION] Expected: "&Questions_Input!D22&" | Actual: "&Questions_Input!I22&" — Please clarify — deviation from expected answer. Add details in Notes column."&IF(Questions_Input!O22<>""," | Details: "&Questions_Input!O22,"")))
A23: 1 | B23: 1.20 | C23: Training of Study Personnel | D23: ==IF(Questions_Input!I23="","— not yet answered —",IF(Questions_Input!J23=FALSE,"Site to immediately notify Study Clinical Lead and Clinical Team."&IF(Questions_Input!O23<>""," | Note: "&Questions_Input!O23,""),"[DEVIATION] Expected: "&Questions_Input!D23&" | Actual: "&Questions_Input!I23&" — Please clarify — deviation from expected answer. Add details in Notes column."&IF(Questions_Input!O23<>""," | Details: "&Questions_Input!O23,"")))
A24: 1 | B24: 1.21 | C24: Training of Study Personnel | D24: ==IF(Questions_Input!I24="","— not yet answered —",IF(Questions_Input!J24=FALSE,"MSLM, CRA, LSAD discussed in detail and site is in agreement."&IF(Questions_Input!O24<>""," | Note: "&Questions_Input!O24,""),"[DEVIATION] Expected: "&Questions_Input!D24&" | Actual: "&Questions_Input!I24&" — Please clarify — deviation from expected answer. Add details in Notes column."&IF(Questions_Input!O24<>""," | Details: "&Questions_Input!O24,"")))
A25: 1 | B25: 1.22 | C25: Training of Study Personnel | D25: ==IF(Questions_Input!I25="","— not yet answered —",IF(Questions_Input!J25=FALSE,"The listed Personnel was fully trained. ICF versions, IP Handling Manual, Biological Sample Handling, ISF and Vendors discussed."&IF(Questions_Input!O25<>""," | Note: "&Questions_Input!O25,""),"[DEVIATION] Expected: "&Questions_Input!D25&" | Actual: "&Questions_Input!I25&" — Please clarify — deviation from expected answer. Add details in Notes column."&IF(Questions_Input!O25<>""," | Details: "&Questions_Input!O25,"")))
A26: 2 | B26: 2.1 | C26: Subject Requirements and Procedures | D26: ==IF(Questions_Input!I26="","— not yet answered —",IF(Questions_Input!J26=FALSE,"PI confirmed 14 patients; first screening/randomization planned YYYY MM DD."&IF(Questions_Input!O26<>""," | Note: "&Questions_Input!O26,""),"[DEVIATION] Expected: "&Questions_Input!D26&" | Actual: "&Questions_Input!I26&" — Please clarify — deviation from expected answer. Add details in Notes column."&IF(Questions_Input!O26<>""," | Details: "&Questions_Input!O26,"")))
A27: 2 | B27: 2.2 | C27: Subject Requirements and Procedures | D27: ==IF(Questions_Input!I27="","— not yet answered —",IF(Questions_Input!J27=FALSE,"See 1.1 regarding Pre-Approval nature of this visit."&IF(Questions_Input!O27<>""," | Note: "&Questions_Input!O27,""),"[DEVIATION] Expected: "&Questions_Input!D27&" | Actual: "&Questions_Input!I27&" — Please clarify — deviation from expected answer. Add details in Notes column."&IF(Questions_Input!O27<>""," | Details: "&Questions_Input!O27,"")))
A28: 2 | B28: 2.3 | C28: Subject Requirements and Procedures | D28: ==IF(Questions_Input!I28="","— not yet answered —",IF(Questions_Input!J28=FALSE,"CRA/LSAD discussed patient-reimbursement and retention. Thank You Cards in German discussed."&IF(Questions_Input!O28<>""," | Note: "&Questions_Input!O28,""),"[DEVIATION] Expected: "&Questions_Input!D28&" | Actual: "&Questions_Input!I28&" — Please clarify — deviation from expected answer. Add details in Notes column."&IF(Questions_Input!O28<>""," | Details: "&Questions_Input!O28,"")))
A29: 3 | B29: 3.1 | C29: IRB/IEC and Regulatory Authority Responsibilities | D29: ==IF(Questions_Input!I29="","— not yet answered —",IF(Questions_Input!J29=FALSE,"Site was informed no patient procedures before sponsor approval via ""Ready To Enrollment""."&IF(Questions_Input!O29<>""," | Note: "&Questions_Input!O29,""),"[DEVIATION] Expected: "&Questions_Input!D29&" | Actual: "&Questions_Input!I29&" — Please clarify — deviation from expected answer. Add details in Notes column."&IF(Questions_Input!O29<>""," | Details: "&Questions_Input!O29,"")))
A30: 3 | B30: 3.2 | C30: IRB/IEC and Regulatory Authority Responsibilities | D30: ==IF(Questions_Input!I30="","— not yet answered —",IF(Questions_Input!J30=FALSE,"NA — Sponsor will report accordingly and inform sites."&IF(Questions_Input!O30<>""," | Note: "&Questions_Input!O30,""),"[DEVIATION] Expected: "&Questions_Input!D30&" | Actual: "&Questions_Input!I30&" — Please clarify — deviation from expected answer. Add details in Notes column."&IF(Questions_Input!O30<>""," | Details: "&Questions_Input!O30,"")))
A31: 3 | B31: 3.3 | C31: IRB/IEC and Regulatory Authority Responsibilities | D31: ==IF(Questions_Input!I31="","— not yet answered —",IF(Questions_Input!J31=FALSE,"Please refer to 3.2."&IF(Questions_Input!O31<>""," | Note: "&Questions_Input!O31,""),"[DEVIATION] Expected: "&Questions_Input!D31&" | Actual: "&Questions_Input!I31&" — Please clarify — deviation from expected answer. Add details in Notes column."&IF(Questions_Input!O31<>""," | Details: "&Questions_Input!O31,"")))
A32: 4 | B32: 4.1 | C32: Monitoring and Source Data Verification | D32: ==IF(Questions_Input!I32="","— not yet answered —",IF(Questions_Input!J32=FALSE,"CRA discussed REMs regularly; main SC is contact; medical queries forwarded to PI/SI."&IF(Questions_Input!O32<>""," | Note: "&Questions_Input!O32,""),"[DEVIATION] Expected: "&Questions_Input!D32&" | Actual: "&Questions_Input!I32&" — Please clarify — deviation from expected answer. Add details in Notes column."&IF(Questions_Input!O32<>""," | Details: "&Questions_Input!O32,"")))
A33: 4 | B33: 4.2 | C33: Monitoring and Source Data Verification | D33: ==IF(Questions_Input!I33="","— not yet answered —",IF(Questions_Input!J33=FALSE,"Site is aware; first RMV after first patient screened."&IF(Questions_Input!O33<>""," | Note: "&Questions_Input!O33,""),"[DEVIATION] Expected: "&Questions_Input!D33&" | Actual: "&Questions_Input!I33&" — Please clarify — deviation from expected answer. Add details in Notes column."&IF(Questions_Input!O33<>""," | Details: "&Questions_Input!O33,"")))
A34: 4 | B34: 4.3 | C34: Monitoring and Source Data Verification | D34: ==IF(Questions_Input!I34="","— not yet answered —",IF(Questions_Input!J34=FALSE,"CRA discussed frequency; site is in agreement."&IF(Questions_Input!O34<>""," | Note: "&Questions_Input!O34,""),"[DEVIATION] Expected: "&Questions_Input!D34&" | Actual: "&Questions_Input!I34&" — Please clarify — deviation from expected answer. Add details in Notes column."&IF(Questions_Input!O34<>""," | Details: "&Questions_Input!O34,"")))
A35: 4 | B35: 4.4 | C35: Monitoring and Source Data Verification | D35: ==IF(Questions_Input!I35="","— not yet answered —",IF(Questions_Input!J35=FALSE,"CRA discussed in detail. Site is in agreement."&IF(Questions_Input!O35<>""," | Note: "&Questions_Input!O35,""),"[DEVIATION] Expected: "&Questions_Input!D35&" | Actual: "&Questions_Input!I35&" — Please clarify — deviation from expected answer. Add details in Notes column."&IF(Questions_Input!O35<>""," | Details: "&Questions_Input!O35,"")))
A36: 4 | B36: 4.5 | C36: Monitoring and Source Data Verification | D36: ==IF(Questions_Input!I36="","— not yet answered —",IF(Questions_Input!J36=FALSE,"Site using printouts/EMR; CRA will get access according to 21 CFR Part 11."&IF(Questions_Input!O36<>""," | Note: "&Questions_Input!O36,""),"[DEVIATION] Expected: "&Questions_Input!D36&" | Actual: "&Questions_Input!I36&" — Please clarify — deviation from expected answer. Add details in Notes column."&IF(Questions_Input!O36<>""," | Details: "&Questions_Input!O36,"")))
A37: 4 | B37: 4.6 | C37: Monitoring and Source Data Verification | D37: ==IF(Questions_Input!I37="","— not yet answered —",IF(Questions_Input!J37=FALSE,"CRA will get access only to study patients according to 21 CFR Part 11."&IF(Questions_Input!O37<>""," | Note: "&Questions_Input!O37,""),"[DEVIATION] Expected: "&Questions_Input!D37&" | Actual: "&Questions_Input!I37&" — Please clarify — deviation from expected answer. Add details in Notes column."&IF(Questions_Input!O37<>""," | Details: "&Questions_Input!O37,"")))
A38: 4 | B38: 4.7 | C38: Monitoring and Source Data Verification | D38: ==IF(Questions_Input!I38="","— not yet answered —",IF(Questions_Input!J38=FALSE,"NA — Site using local lab for quick check; Central Lab used in general."&IF(Questions_Input!O38<>""," | Note: "&Questions_Input!O38,""),"[DEVIATION] Expected: "&Questions_Input!D38&" | Actual: "&Questions_Input!I38&" — Please clarify — deviation from expected answer. Add details in Notes column."&IF(Questions_Input!O38<>""," | Details: "&Questions_Input!O38,"")))
A39: 4 | B39: 4.8 | C39: Monitoring and Source Data Verification | D39: ==IF(Questions_Input!I39="","— not yet answered —",IF(Questions_Input!J39=FALSE,"CRA discussed all applicable study patient data need to be reviewed on an ongoing basis."&IF(Questions_Input!O39<>""," | Note: "&Questions_Input!O39,""),"[DEVIATION] Expected: "&Questions_Input!D39&" | Actual: "&Questions_Input!I39&" — Please clarify — deviation from expected answer. Add details in Notes column."&IF(Questions_Input!O39<>""," | Details: "&Questions_Input!O39,"")))
A40: 5 | B40: 5.1 | C40: Study Drug | D40: ==IF(Questions_Input!I40="","— not yet answered —",IF(Questions_Input!J40=FALSE,"CRA checked the facility and considered it adequate."&IF(Questions_Input!O40<>""," | Note: "&Questions_Input!O40,""),"[DEVIATION] Expected: "&Questions_Input!D40&" | Actual: "&Questions_Input!I40&" — Please clarify — deviation from expected answer. Add details in Notes column."&IF(Questions_Input!O40<>""," | Details: "&Questions_Input!O40,"")))
...
